Workbook

Sheet Venue Level Data
A1: TAIV BARS AND RESTAURANTS
A2: ClientID | B2: Venue | C2: Venue Type | D2: Market | E2: State | F2: Impressions | G2: Plays | H2: ScreensAtLocation
A3: -NKyY24mM7F_24N1CBGP | B3: Beaver Bar | C3: =VLOOKUP(A3,Sheet2!A:C, 3, FALSE) -> Entertainment|Bars | D3: Phoenix | E3: =VLOOKUP(A3,Sheet2!A:E, 5, FALSE) -> AZ | F3: 17910.878 | G3: 406 | H3: 3
A4: -NN3_Fzj4OfkOLwT7YiX | B4: Divided Vine | C4: =VLOOKUP(A4,Sheet2!A:C, 3, FALSE) -> Entertainment|Bars | D4: Phoenix | E4: =VLOOKUP(A4,Sheet2!A:E, 5, FALSE) -> AZ | F4: 987.72817 | G4: 286 | H4: 2
A5: -Nor7k92yNrGjV5uogb3 | B5: Yo Pauly's Pizza | C5: =VLOOKUP(A5,Sheet2!A:C, 3, FALSE) -> Entertainment|Casual Dining | D5: Phoenix | E5: =VLOOKUP(A5,Sheet2!A:E, 5, FALSE) -> AZ | F5: 6089.1418 | G5: 424 | H5: 4
A6: -Nt3-7ndpSvJdtT87yiG | B6: Tavern Grille Scottsdale | C6: =VLOOKUP(A6,Sheet2!A:C, 3, FALSE) -> Entertainment|Casual Dining | D6: Phoenix | E6: =VLOOKUP(A6,Sheet2!A:E, 5, FALSE) -> AZ | F6: 13505.13 | G6: 272 | H6: 2
A7: -NvhXU3G_ByXt1osJ2sk | B7: Pour Decisions Patio & Kitchen | C7: =VLOOKUP(A7,Sheet2!A:C, 3, FALSE) -> Entertainment|Casual Dining | D7: Phoenix | E7: =VLOOKUP(A7,Sheet2!A:E, 5, FALSE) -> AZ | F7: 2158.564 | G7: 179 | H7: 2
A8: -NoxZXEHFb3dPADRKlx- | B8: Lil Capo Pizzeria - Westgate | C8: =VLOOKUP(A8,Sheet2!A:C, 3, FALSE) -> Entertainment|Casual Dining | D8: Phoenix | E8: =VLOOKUP(A8,Sheet2!A:E, 5, FALSE) -> AZ | F8: 6066.1774 | G8: 339 | H8: 2
A9: -O-mf2jWNsnUBHVHaBDn | B9: University Sports Grill | C9: =VLOOKUP(A9,Sheet2!A:C, 3, FALSE) -> Entertainment|Casual Dining | D9: Phoenix | E9: =VLOOKUP(A9,Sheet2!A:E, 5, FALSE) -> AZ | F9: 7084.421 | G9: 239 | H9: 4
A10: -NzA-WIXsqac5doheXDi | B10: The rib shop | C10: =VLOOKUP(A10,Sheet2!A:C, 3, FALSE) -> Entertainment|Bars | D10: Phoenix | E10: =VLOOKUP(A10,Sheet2!A:E, 5, FALSE) -> AZ | F10: 2621.8756 | G10: 448 | H10: 4
A11: -NoIx1qE9Nsqosy8x0GR | B11: IL Capo Pizzeria | C11: =VLOOKUP(A11,Sheet2!A:C, 3, FALSE) -> Entertainment|Casual Dining | D11: Phoenix | E11: =VLOOKUP(A11,Sheet2!A:E, 5, FALSE) -> AZ | F11: 2218.8967 | G11: 124 | H11: 2
A12: -NtwoHKumPGrfpO1LZgS | B12: Batchelor's Pad BBQ | C12: =VLOOKUP(A12,Sheet2!A:C, 3, FALSE) -> Entertainment|Casual Dining | D12: Phoenix | E12: =VLOOKUP(A12,Sheet2!A:E, 5, FALSE) -> AZ | F12: 1642.1973 | G12: 216 | H12: 2
A13: -O5KQsxzHNOf0LbXnvtR | B13: Union Grill and Tap | C13: =VLOOKUP(A13,Sheet2!A:C, 3, FALSE) -> Entertainment|Casual Dining | D13: Phoenix | E13: =VLOOKUP(A13,Sheet2!A:E, 5, FALSE) -> AZ | F13: 12070.742 | G13: 394 | H13: 4
A14: -NLNqoKPZaMyk66ucxUR | B14: Metro Sports Bar and Billiards | C14: =VLOOKUP(A14,Sheet2!A:C, 3, FALSE) -> Entertainment|Bars | D14: Phoenix | E14: =VLOOKUP(A14,Sheet2!A:E, 5, FALSE) -> AZ | F14: 39914.303 | G14: 1640 | H14: 16
... A137: -OJVc-aSS-ywMDJ3PWs0 | B137: Scotland Yard - The Pub | C137: =VLOOKUP(A137,Sheet2!A:C, 3, FALSE) -> Entertainment|Bars | D137: San Diego | E137: =VLOOKUP(A137,Sheet2!A:E, 5, FALSE) -> CA | F137: 1538.9123 | G137: 86 | H137: 2
A138: -O4vKUnAFcZgZPrmFDss | B138: Red Pepper Taqueria - Dunwoody | C138: =VLOOKUP(A138,Sheet2!A:C, 3, FALSE) -> Entertainment|Casual Dining | D138: Atlanta | E138: FL | F138: 9376.6282 | G138: 524 | H138: 4
A139: -O5sQuxBEF-KjSyzE38g | B139: Hogg Daddy's | C139: =VLOOKUP(A139,Sheet2!A:C, 3, FALSE) -> Entertainment|Bars | D139: Tampa Bay | E139: =VLOOKUP(A139,Sheet2!A:E, 5, FALSE) -> FL | F139: 7336.6747 | G139: 410 | H139: 4
A140: -Mek9YBX0kvGE5Di7oqG | B140: Big Dog Station | C140: =VLOOKUP(A140,Sheet2!A:C, 3, FALSE) -> Entertainment|Casual Dining | D140: Miami | E140: =VLOOKUP(A140,Sheet2!A:E, 5, FALSE) -> FL | F140: 10921.566 | G140: 525 | H140: 3
A141: -Mx4rSl3yiwwqCW0XijQ | B141: Birdie's Pub | C141: =VLOOKUP(A141,Sheet2!A:C, 3, FALSE) -> Entertainment|Bars | D141: Tampa Bay | E141: =VLOOKUP(A141,Sheet2!A:E, 5, FALSE) -> FL | F141: 5821.0232 | G141: 492 | H141: 4
A142: -NxxWAf2h3mbnHD6YxvX | B142: Machupicchu Peruvian Cuisine | C142: =VLOOKUP(A142,Sheet2!A:C, 3, FALSE) -> Entertainment|Casual Dining | D142: Miami | E142: =VLOOKUP(A142,Sheet2!A:E, 5, FALSE) -> FL | F142: 1067.9236 | G142: 421 | H142: 2
A143: -O6gmH5bhhdlACXbfHpw | B143: The Chill Room Lake Worth Beach | C143: =VLOOKUP(A143,Sheet2!A:C, 3, FALSE) -> Retail|Dispensaries | D143: Miami | E143: =VLOOKUP(A143,Sheet2!A:E, 5, FALSE) -> FL | F143: 4580.9481 | G143: 256 | H143: 1
A144: -MrEYhB038IikhW11S5- | B144: Even Keel Fish Shack | C144: =VLOOKUP(A144,Sheet2!A:C, 3, FALSE) -> Entertainment|Casual Dining | D144: Miami | E144: =VLOOKUP(A144,Sheet2!A:E, 5, FALSE) -> FL | F144: 1875.4078 | G144: 694 | H144: 4
A145: -NAtTAcu34_4uRnzBTSa | B145: The Par Pub | C145: =VLOOKUP(A145,Sheet2!A:C, 3, FALSE) -> Entertainment|Bars | D145: Tampa Bay | E145: =VLOOKUP(A145,Sheet2!A:E, 5, FALSE) -> FL | F145: 4090.087 | G145: 441 | H145: 2
A146: -OJPo573jcRAGSbaLZgN | B146: Play By Play Sports Bar and Grill | C146: =VLOOKUP(A146,Sheet2!A:C, 3, FALSE) -> Entertainment|Casual Dining | D146: Miami | E146: =VLOOKUP(A146,Sheet2!A:E, 5, FALSE) -> FL | F146: 14375.038 | G146: 645 | H146: 4
A147: -MZww_GNQba-ycEVf6gy | B147: Temple Street Eatery | C147: =VLOOKUP(A147,Sheet2!A:C, 3, FALSE) -> Entertainment|Casual Dining | D147: Miami | E147: =VLOOKUP(A147,Sheet2!A:E, 5, FALSE) -> FL | F147: 8984.1332 | G147: 423 | H147: 2
A148: -NyRmpnENv71dY1zdMGC | B148: The Kenwood | C148: =VLOOKUP(A148,Sheet2!A:C, 3, FALSE) -> Entertainment|Bars | D148: Tampa Bay | E148: =VLOOKUP(A148,Sheet2!A:E, 5, FALSE) -> FL | F148: 6397.3093 | G148: 541 | H148: 5
A149: -Nm6dZN5fLR5oHiO35Ra | B149: Autentica Taqueria | C149: =VLOOKUP(A149,Sheet2!A:C, 3, FALSE) -> Entertainment|Casual Dining | D149: Miami | E149: =VLOOKUP(A149,Sheet2!A:E, 5, FALSE) -> FL | F149: 1370.1974 | G149: 485 | H149: 2
A150: -Me68kpYuJvSn-sGCagD | B150: Mis-Cue Lounge | C150: =VLOOKUP(A150,Sheet2!A:C, 3, FALSE) -> Entertainment|Bars | D150: Miami | E150: =VLOOKUP(A150,Sheet2!A:E, 5, FALSE) -> FL | F150: 18503.494 | G150: 446 | H150: 3
... A178: -Mq1WI0CJ2m5kUSp8dAV | B178: Papa’s Raw Bar | C178: =VLOOKUP(A178,Sheet2!A:C, 3, FALSE) -> Entertainment|Casual Dining | D178: Miami | E178: =VLOOKUP(A178,Sheet2!A:E, 5, FALSE) -> FL | F178: 42443.663 | G178: 802 | H178: 3
A179: -OaenoaeVQiceQ82880v | B179: Tootsie's Cabaret Miami | C179: =VLOOKUP(A179,Sheet2!A:C, 3, FALSE) -> #N/A | D179: Miami | E179: FL | F179: 7068.2598 | G179: 395 | H179: 3
A180: -OVK0EsyRITkzszoYTP6 | B180: Wicked Cantina - Sarasota (Downtown) | C180: =VLOOKUP(A180,Sheet2!A:C, 3, FALSE) -> Entertainment|Casual Dining | D180: Tampa Bay | E180: =VLOOKUP(A180,Sheet2!A:E, 5, FALSE) -> FL | F180: 11470.265 | G180: 641 | H180: 5
A181: -NN8gjonmznHbkKA37nB | B181: Cotee River Brewing Company | C181: =VLOOKUP(A181,Sheet2!A:C, 3, FALSE) -> Entertainment|Bars | D181: Tampa Bay | E181: =VLOOKUP(A181,Sheet2!A:E, 5, FALSE) -> FL | F181: 5724.1409 | G181: 305 | H181: 2
A182: -MrOD9UGCxMw0Flu5Tkt | B182: Ray’s Hideaway | C182: =VLOOKUP(A182,Sheet2!A:C, 3, FALSE) -> Entertainment|Casual Dining | D182: Miami | E182: =VLOOKUP(A182,Sheet2!A:E, 5, FALSE) -> FL | F182: 11265.378 | G182: 503 | H182: 5
A183: -NSpyBluUYWj-2npe69o | B183: OLLIES ON THE BEACH | C183: =VLOOKUP(A183,Sheet2!A:C, 3, FALSE) -> Entertainment|Casual Dining | D183: Tampa Bay | E183: =VLOOKUP(A183,Sheet2!A:E, 5, FALSE) -> FL | F183: 1968.8191 | G183: 618 | H183: 4
A184: -OSuKhhtpMuav1FiT0ze | B184: Beef 'O' Brady's - Lakewood Ranch | C184: =VLOOKUP(A184,Sheet2!A:C, 3, FALSE) -> Entertainment|Casual Dining | D184: Tampa Bay | E184: =VLOOKUP(A184,Sheet2!A:E, 5, FALSE) -> FL | F184: 13098.649 | G184: 732 | H184: 5
A185: -NWmaaeVbFYIxOJ1ZCPk | B185: Frenchy's South Beach Cafe | C185: =VLOOKUP(A185,Sheet2!A:C, 3, FALSE) -> Entertainment|Casual Dining | D185: Tampa Bay | E185: =VLOOKUP(A185,Sheet2!A:E, 5, FALSE) -> FL | F185: 8207.4885 | G185: 301 | H185: 2
A186: -N4E0J9JgupmCllp_avl | B186: Sculley's | C186: =VLOOKUP(A186,Sheet2!A:C, 3, FALSE) -> Entertainment|Casual Dining | D186: Tampa Bay | E186: =VLOOKUP(A186,Sheet2!A:E, 5, FALSE) -> FL | F186: 6172.2592 | G186: 440 | H186: 3
A187: -OMN4c6SJnIHy85GllBb | B187: Wicked Cantina - Bradenton Beach | C187: =VLOOKUP(A187,Sheet2!A:C, 3, FALSE) -> Entertainment|Casual Dining | D187: Tampa Bay | E187: =VLOOKUP(A187,Sheet2!A:E, 5, FALSE) -> FL | F187: 5113.9737 | G187: 459 | H187: 4
A188: -N6il_guoHS36867z0lM | B188: Bar 23fifty | C188: =VLOOKUP(A188,Sheet2!A:C, 3, FALSE) -> Entertainment|Casual Dining | D188: Tampa Bay | E188: =VLOOKUP(A188,Sheet2!A:E, 5, FALSE) -> FL | F188: 1517.5486 | G188: 299 | H188: 3
A189: -ONVOUUXNLvazHrXVn8R | B189: Scoreboard Social | C189: =VLOOKUP(A189,Sheet2!A:C, 3, FALSE) -> Entertainment|Casual Dining | D189: Other | E189: =VLOOKUP(A189,Sheet2!A:E, 5, FALSE) -> FL | F189: 6692.4789 | G189: 374 | H189: 3
...

Sheet State Level Data
A1: TAIV BARS AND RESTAURANTS
A2: state | B2: impressions | C2: plays | D2: spend
A3: AZ | B3: 259631.52 | C3: 10766 | D3: 2596.32
A4: CA | B4: 723713.96 | C4: 40374 | D4: 7737.14
A5: FL | B5: 833498.58 | C5: 37184 | D5: 8334.99
A6: GA | B6: 268212.78 | C6: 12650 | D6: 2622.13
A7: IL | B7: 406065.21 | C7: 15599 | D7: 4560.65
A8: TX | B8: 944701.25 | C8: 41844 | D8: 9947.25
A9: Total | B9: =SUM(B3:B8) -> 3435823.3 | C9: =SUM(C3:C8) -> 158417 | D9: 35798.38
A11: TAIV RETAIL
A13: state | B13: impressions | C13: plays | D13: spend
A14: AL | B14: 1047707 | C14: 173110 | D14: 368.16
A15: AZ | B15: 959682.53 | C15: 209671 | D15: 499.65
A16: CA | B16: 3375977.3 | C16: 869479 | D16: 1761.93
A17: DC | B17: 206858.41 | C17: 40894 | D17: 78.89
A18: DE | B18: 547354.5 | C18: 84128 | D18: 210.38
A19: FL | B19: 3218573.5 | C19: 849659 | D19: 1893.42
A20: GA | B20: 1537669.6 | C20: 593462 | D20: 1183.38
A21: ID | B21: 10547.26 | C21: 6718 | D21: 52.59
A22: IL | B22: 2158186.9 | C22: 630141 | D22: 1367.47
A23: MN | B23: 552694.34 | C23: 132231 | D23: 315.57
A24: MO | B24: 708491.82 | C24: 209179 | D24: 394.46
A25: MS | B25: 386977.19 | C25: 90113 | D25: 157.78
... A35: WI | B35: 1716854.2 | C35: 420098 | D35: 867.82
A36: total | B36: =SUM(B14:B35) -> 26841066 | C36: =SUM(C14:C35) -> 7200462 | D36: 15384

Sheet Creative Level Data
A1: TAIV BARS AND RESTAURANTS
A2: SlideId | B2: SlideName | C2: ImageName | D2: Impressions | E2: Plays
A3: -OYrg9wHWxhr1xQxArVJ | B3: Betonline - August Ncaa Ad.mp4 | C3: 1756502316530-Betonline - August Ncaa Ad.mp4 | D3: 270544.85 | E3: 11623
A4: -Ob4m-EbQs8mu_fqwfC2 | B4: Justin herbert - BO AD.mp4 | C4: 1759959978415-Justin herbert - BO AD.mp4 | D4: 1115230.8 | E4: 52196
A5: -Ob4m4_tjIaOwngh7j8g | B5: Justin herbert - BO AD.mp4 | C5: 1759960001567-Justin herbert - BO AD.mp4 | D5: 312824.14 | E5: 14243
A6: -OcBpRtGjyR0gomk9Dw3 | B6: NBA_WK43_Betonline.mp4 | C6: 1761151924886-NBA_WK43_Betonline.mp4 | D6: 1141994.6 | E6: 54495
A7: -OcLrNw8q7xOschyCGYK | B7: Oct24_MLB.mp4 | C7: 1761320205347-Oct24_MLB.mp4 | D7: 50031.053 | E7: 2430
A8: -Oe2SWhz1Oyd0Ufz_DQS | B8: BetOnline Temp.mp4 | C8: 1763142230983-BetOnline Temp.mp4 | D8: 396955.77 | E8: 17969
A9: -OewcZVPYNZ3TRByIr7C | B9: Untitled design (2).mp4 | C9: 1764101500393-Untitled design (2).mp4 | D9: 148242.01 | E9: 5461
A11: TAIV RETAIL
A12: slideId | B12: slideName | C12: imageName | D12: impressions | E12: plays
A13: -OYr_M4Gqrx5eTdGGAON | B13: Betonline - August Ncaa Ad.mp4 | C13: 1756500528025-Betonline - August Ncaa Ad.mp4 | D13: 37710.24 | E13: 10493
A14: -OZskSDeS434sK4w16hP | B14: BetOnline - NFL (DALLASSF)..mp4 | C14: 1757593950113-BetOnline - NFL (DALLASSF)..mp4 | D14: 8.54 | E14: 2
A15: -Oa0NwAhG8iWxgizsg3v | B15: Copy of BetOnline - NFL (DALLASSF)..mp4 | C15: 1758812528255-Copy of BetOnline - NFL (DALLASSF)..mp4 | D15: 21557.27 | E15: 6370
A16: -Oauw_dhjlDqBy-VVrYK | B16: Justin herbert - BO AD.mp4 | C16: 1759778201590-Justin herbert - BO AD.mp4 | D16: 26145869 | E16: 7010211
A17: -Ob4oFBtP6mXXLKlVJZw | B17: Justin herbert - BO AD.mp4 | C17: 1759960570991-Justin herbert - BO AD.mp4 | D17: 16903.4 | E17: 4861
A18: -Ob4oHGiK6VFMdJfuCO5 | B18: Justin herbert - BO AD.mp4 | C18: 1759960579657-Justin herbert - BO AD.mp4 | D18: 16484.03 | E18: 4626
A19: -Ob4oJII28aMgiWTRogc | B19: Justin herbert - BO AD.mp4 | C19: 1759960587921-Justin herbert - BO AD.mp4 | D19: 16378.55 | E19: 4641
A20: -Ob4oXNY2JbC_TYAuN_C | B20: Justin herbert - BO AD.mp4 | C20: 1759960645421-Justin herbert - BO AD.mp4 | D20: 16188.71 | E20: 4617
A21: -Ob4oZUpQPOEXwgHi2Lw | B21: Justin herbert - BO AD.mp4 | C21: 1759960653786-Justin herbert - BO AD.mp4 | D21: 41723.85 | E21: 11502
A22: -Ob4ogkC4tjsmu-4yCSJ | B22: BetOnline - MLB(OCT).mp4 | C22: 1759960661373-BetOnline - MLB(OCT).mp4 | D22: 16437.74 | E22: 4612
A23: -Ob4onZxLd8AzmYolkLi | B23: Justin herbert - BO AD.mp4 | C23: 1759960715573-Justin herbert - BO AD.mp4 | D23: 16099.04 | E23: 4614
A24: -OcBqC5aXielx9xFB5NR | B24: NBA_WK43_Betonline.mp4 | C24: 1761152122631-NBA_WK43_Betonline.mp4 | D24: 417349.07 | E24: 112187
... A27: -OewcfMgBEYwxwSpP1kU | B27: Untitled design (2).mp4 | C27: 1764101512032-Untitled design (2).mp4 | D27: 15512.54 | E27: 4223

Sheet Spend By Day
A1: TAIV BARS AND RESTAURANTS
A2: Date | B2: Impressions | C2: Plays | D2: Spend
A3: 45962 | B3: 103917.79 | C3: 5154 | D3: 1167
A4: 45963 | B4: 85337.978 | C4: 4215 | D4: 1167
A5: 45964 | B5: 117633.48 | C5: 5700 | D5: 535
A6: 45965 | B6: 108871.32 | C6: 5443 | D6: 535
A7: 45966 | B7: 60596.608 | C7: 2981 | D7: 535
A8: 45967 | B8: 122856.85 | C8: 5925 | D8: 1707
A9: 45968 | B9: 138060.62 | C9: 6792 | D9: 1707
A10: 45969 | B10: 137786.79 | C10: 6701 | D10: 1707
A11: 45970 | B11: 104650.32 | C11: 5109 | D11: 1707
A12: 45971 | B12: 85850.706 | C12: 4167 | D12: 535.18
A13: 45972 | B13: 49515.898 | C13: 2432 | D13: 535
A14: 45973 | B14: 54046.188 | C14: 2568 | D14: 535
... A28: 45987 | B28: 70072.591 | C28: 2769 | D28: 116.67
A29: 45988 | B29: 162366.76 | C29: 4846 | D29: 1586.666 | F29: .
A30: 45989 | B30: 206020.23 | C30: 7133 | D30: 1586.666
A31: 45990 | B31: 180267.68 | C31: 7372 | D31: 1586.666
A32: 45991 | B32: 165715.3 | C32: 7324 | D32: 1586.666
A33: Total | B33: =SUM(B3:B32) -> 3435823.3 | C33: =SUM(C3:C32) -> 158417 | D33: =SUM(D3:D32) -> 35798.41
A35: TAIV RETAIL
A37: date | B37: impressions | C37: plays | D37: spend
A38: 45962 | B38: 1769195.7 | C38: 475125 | D38: 690
A39: 45963 | B39: 1554101.9 | C39: 421242 | D39: 690
A40: 45964 | B40: 1893941.2 | C40: 507144 | D40: 247
A41: 45965 | B41: 597768.59 | C41: 161495 | D41: 247
A42: 45966 | B42: 226666.79 | C42: 58975 | D42: 247
A43: 45967 | B43: 1543242.7 | C43: 413816 | D43: 690
A44: 45968 | B44: 1911580.9 | C44: 515665 | D44: 690
A45: 45969 | B45: 1869106.6 | C45: 504929 | D45: 690
A46: 45970 | B46: 1688881 | C46: 456005 | D46: 690
A47: 45971 | B47: 1925531 | C47: 512707 | D47: 247
A48: 45972 | B48: 809525.43 | C48: 216926 | D48: 247
A49: 45973 | B49: 377395.68 | C49: 99051 | D49: 247
... A67: 45991 | B67: 69343.05 | C67: 18548 | D67: 690
A68: total | B68: =SUM(B38:B67) -> 26841066 | C68: =SUM(C38:C67) -> 7200462 | D68: =SUM(D38:D67) -> 15384

Sheet Sheet2
A1: Firebase Id | B1: IAB Venue Type | C1: Vistar Venue Type | D1: Account Name | E1: Shipping State/Province | F1: Account ID | G1: Revenue Share Percentage | H1: DMA
A2: -Lm89I_2XS4Taz6KQV7u | B2: Entertainment | Restaurant and Bar | C2: Entertainment|Casual Dining | D2: Fionns Grant Park | E2: MB | F2: 001OG000016zOVF | G2: 15 | H2: WINNIPEG
A3: -N7vB4glPqShJ1qEHZau | B3: Entertainment | Restaurant and Bar | C3: Entertainment|Bars | D3: Taiv HQ | E3: TX | F3: 0018V00002RiBln | G3: 15 | H3: SAN ANTONIO
A4: -NVfdTVT2B7L9M4DW-uK | B4: Entertainment | Restaurant and Bar | C4: Entertainment|Casual Dining | D4: Paddy Kelly's | E4: MA | F4: 001OG000019i3Xb | G4: 15 | H4: BOSTON (MANCHESTER)
A5: -O9M57k5rIUKvFdpgX4O | B5: Entertainment | Restaurant and Bar | C5: Entertainment|Casual Dining | D5: Horus Cafe | E5: NY | F5: 0018V00002f5kWa | G5: 15 | H5: NEW YORK
A6: -O9WJ2SlG98VV_CKfYaP | B6: Entertainment | Restaurant and Bar | C6: Entertainment|Casual Dining | D6: Shotzee's Bar And Grill | E6: TX | F6: 0018V00002hB8TI | G6: 15 | H6: DALLAS - FT. WORTH
A7: -O_CyzMLiCsHEy0Fka16 | B7: Entertainment | Restaurant and Bar | C7: Entertainment|Casual Dining | D7: Wonder Bar | E7: NJ | F7: 001OG000016yDuO | G7: 15 | H7: PHILADELPHIA
A8: -O_Czs_45eSb_6t3Phb5 | B8: Entertainment | Restaurant and Bar | C8: Entertainment|Casual Dining | D8: Dooney's Pub Voorhees | E8: NJ | F8: 001OG000018R0na | G8: 15 | H8: PHILADELPHIA
A9: -O_D-Sxw48a26HdIwQug | B9: Entertainment | Restaurant and Bar | C9: Entertainment|Casual Dining | D9: Dooney's Pub Delran | E9: NJ | F9: 001OG000018Qt99 | G9: 15 | H9: PHILADELPHIA
A10: -O_D1YnHKYI4O12HfWo- | B10: Entertainment | Restaurant and Bar | C10: Entertainment|Casual Dining | D10: Patrizia's Taverna | E10: NY | F10: 001OG000017J7yw | G10: 15 | H10: NEW YORK
A11: -O_Ddul1kBg8t-1ZI3CW | B11: Entertainment | Restaurant and Bar | C11: Entertainment|Casual Dining | D11: Pikes Cinema Bar and Grill | E11: MD | F11: 001OG000016ueKm | G11: 15 | H11: BALTIMORE
A12: -O_DgPsRfCybGjUKPONk | B12: Entertainment | Restaurant and Bar | C12: Entertainment|Bars | D12: Del Webb Lakewood Ranch Lake House | E12: FL | F12: 001OG000018YsSH | G12: 15 | H12: TAMPA - ST. PETE (SARASOTA)
A13: -O_DgSV0jE3wCUe-w7W3 | B13: Entertainment | Restaurant and Bar | C13: Entertainment|Casual Dining | D13: Element Restaurant & Bar | E13: NJ | F13: 001OG000018R0KE | G13: 15 | H13: NEW YORK
... A125: -ObY8tmwM7Ao_GTe8Q3v | B125: Entertainment | Restaurant and Bar | C125: Entertainment|Casual Dining | D125: Cagney's | E125: MA | F125: 001OG000010cAvU | G125: 15 | H125: BOSTON (MANCHESTER)
A126: -ObYYBUZCzBcK8jRU-CW | B126: Entertainment | Restaurant and Bar | C126: Entertainment|Casual Dining | D126: Shell Shack HO | E126: TX | F126: 001OG00001Abv4H | H126: DALLAS - FT. WORTH
A127: -ObZ29cn65HHsRWuOGVN | B127: Entertainment | Restaurant and Bar | C127: Entertainment|Casual Dining | D127: Village Tavern | Bar & grill | E127: MA | F127: 001OG000010c6bW | G127: 15 | H127: BOSTON (MANCHESTER)
A128: -ObZJLWbRo16k9hzWNvD | B128: Entertainment | Restaurant and Bar | C128: Entertainment|Bars | D128: Water's Edge Bar & Grill | E128: MO | F128: 001OG000019l7yB | G128: 15 | H128: KANSAS CITY
A129: -ObZK1Kr4KB3y8z3PA2o | B129: Entertainment | Restaurant and Bar | C129: Entertainment|Bars | D129: Edge on 7 Bar & Grill | E129: MO | F129: 001OG000019lKVY | G129: 15 | H129: KANSAS CITY
A130: -Oc1v_L4RIPb3uzdQmCZ | B130: Entertainment | Restaurant and Bar | C130: Entertainment|Casual Dining | D130: Hermosa Brewing Company - Hermosa Beach | E130: CA | F130: 001OG00000uoXWl | G130: 15 | H130: LOS ANGELES
A131: -Oc1yXXkafD_XW1CiDyA | B131: Entertainment | Restaurant and Bar | C131: Entertainment|Casual Dining | D131: Hermosa Brewing Company Torrance | E131: CA | F131: 001OG00000uoP0m | G131: 15 | H131: LOS ANGELES
A132: -Oc2J1u8VZRIs_sQaFcA | B132: Entertainment | Restaurant and Bar | C132: Entertainment|Bars | D132: Olde Town Tavern and Grill | E132: CO | F132: 001OG000019lLro | G132: 15 | H132: DENVER
A133: -Oc6d7Dzz-k3Yy3FMOyH | B133: Entertainment | Restaurant and Bar | C133: Entertainment|Bars | D133: The Bar West Plaza | E133: MO | F133: 001OG000019lK4J | G133: 15 | H133: KANSAS CITY
A134: -Oc7Cb5Ig_MFr74FCduV | B134: Entertainment | Restaurant and Bar | C134: Entertainment|Casual Dining | D134: Orangedale Lounge | E134: AZ | F134: 001OG00001AJCOz | G134: 15 | H134: PHOENIX (PRESCOTT)
A135: -Oc7PkVYWXh1T5-OHyTK | B135: Entertainment | Restaurant and Bar | C135: Entertainment|Casual Dining | D135: Turtle Bay | E135: LA | F135: 001OG0000181s1H | G135: 15 | H135: NEW ORLEANS
A136: -OcbaSd8n289b4TF6bwi | B136: Entertainment | Restaurant and Bar | C136: Entertainment|Casual Dining | D136: Hook & Reel Cajun Seafood & Bar - Denver | E136: CO | F136: 001OG00001ARP5i | G136: 15 | H136: DENVER
A137: -OcBcyjKzkR0o3scyAOw | B137: Entertainment | Restaurant and Bar | C137: Entertainment|Casual Dining | D137: Ott's Greentop | E137: NJ | F137: 001OG000018QyGl | G137: 15 | H137: PHILADELPHIA
A138: -OcBdoq0GN-c4bKBuS1h | B138: Entertainment | Restaurant and Bar | C138: Entertainment|Casual Dining | D138: Braddock's Tavern | E138: NJ | F138: 001OG000018Qt96 | G138: 15 | H138: PHILADELPHIA
... A147: -OckiVL3ZeUAhqdHptyI | B147: Entertainment | Restaurant and Bar | C147: Entertainment|Casual Dining | D147: PlayMakers Sports Bar & Grill | E147: MO | F147: 001OG00001AGYQQ | G147: 15 | H147: ST. LOUIS
A148: -OckkHIwHwesl_Alpw5g | B148: Entertainment | Restaurant and Bar | C148: Entertainment|Casual Dining | D148: Drake's Paddock Shops | E148: KY | F148: 001OG00001ANxsM | H148: LOUISVILLE
A149: -OckqNFu8a3f2wm3tfi5 | B149: Entertainment | Restaurant and Bar | C149: Entertainment|Casual Dining | D149: Timber Creek Grill | E149: MO | F149: 001OG00001AGdME | G149: 15 | H149: ST. LOUIS
A150: -OckZnznwPETT83dXyxq | B150: Entertainment | Restaurant and Bar | C150: Entertainment|Bars | D150: Gibsons Bar & Steakhouse (Rosemont) | E150: IL | F150: 0018V00002fiUTi | G150: 15 | H150: CHICAGO
A151: -Ocl3YURzB3hqWpNCihW | B151: Entertainment | Restaurant and Bar | C151: Entertainment|Casual Dining | D151: Oskar Blues Grill & Brew - Colorado Springs | E151: CO | F151: 001OG00001B4w8E | G151: 15 | H151: COLORADO SPRINGS - PUEBLO
A152: -OclfIL7DihFnUotOLl- | B152: Entertainment | Restaurant and Bar | C152: Entertainment|Casual Dining | D152: The Rally Sports Bar & Grille | E152: RI | F152: 001OG00001B5Kgn | G152: 15 | H152: PROVIDENCE - NEW BEDFORD
A153: -OclfiT7G9-yMrOuFRe3 | B153: Entertainment | Restaurant and Bar | C153: Entertainment|Casual Dining | D153: O'Rourkes Bar & Grill | E153: RI | F153: 001OG00001B5LmX | G153: 15 | H153: PROVIDENCE - NEW BEDFORD
A154: -OclIv76luGq0F9mIcjN | B154: Entertainment | Restaurant and Bar | C154: Entertainment|Casual Dining | D154: 1356 Public House | E154: MO | F154: 001OG00001AGc6R | G154: 15 | H154: ST. LOUIS
A155: -OcllBz-_Oq2RcqRRPJ1 | B155: Entertainment | Restaurant and Bar | C155: Entertainment|Casual Dining | D155: Birch & Bay Roofdeck Coastal Kitchen | E155: RI | F155: 001OG00001B5Hr0 | G155: 15 | H155: PROVIDENCE - NEW BEDFORD
A156: -Oclp0GbFp15zpdGNvHe | B156: Entertainment | Restaurant and Bar | C156: Entertainment|Casual Dining | D156: Locales Taco + Tequila Bar | E156: CO | F156: 001OG00001AQT4x | G156: 15 | H156: DENVER
A157: -OcN4z_w5d-HtdCImEyB | B157: Entertainment | Restaurant and Bar | C157: Entertainment|Bars | D157: Jake's Roadhouse | E157: CO | F157: 001OG000019lLOR | G157: 15 | H157: DENVER
A158: -Ocqbxj99WaFEDsmBHWs | B158: Entertainment | Restaurant and Bar | C158: Entertainment|Casual Dining | D158: Lazy Dog Restaurant & Bar - Garland | E158: TX | F158: 001OG00001A9SZo | H158: DALLAS - FT. WORTH
A159: -Ocqc15Eq3BT-LtKoOQN | B159: Entertainment | Restaurant and Bar | C159: Entertainment|Casual Dining | D159: Lazy Dog Restaurant & Bar - Irvine | E159: CA | F159: 001OG00001A9SZ9 | H159: LOS ANGELES
...
