Workbook

Sheet Venue Level Data
A1: BARS/RESTAURANT
A2: clientId | B2: venue | C2: venue type | D2: market | E2: state | F2: lat | G2: long | H2: impressions | I2: plays | J2: ScreensAtLocation
A3: -N5kSlRHmio6DwYusF1r | B3: Tim Finnegans Irish Pub | C3: =VLOOKUP(A3,sf!A:C, 3, FALSE) -> Entertainment|Casual Dining | D3: Miami | E3: =VLOOKUP(A3,sf!A:E, 5, FALSE) -> FL | F3: 26.428052 | G3: -80.072529 | H3: 2653.2522 | I3: 78 | J3: 2
A4: -O4qDraoG1VZOsjpFOn4 | B4: Twain's Brewpub & Billiards | C4: =VLOOKUP(A4,sf!A:C, 3, FALSE) -> Entertainment|Casual Dining | D4: Atlanta | E4: =VLOOKUP(A4,sf!A:E, 5, FALSE) -> GA | F4: 33.772441 | G4: -84.294624 | H4: 5547.2419 | I4: 310 | J4: 4
A5: -O3sM6VjrPiAHBJ6Em2g | B5: Federal American Grill - Shepherd | C5: =VLOOKUP(A5,sf!A:C, 3, FALSE) -> Entertainment|Casual Dining | D5: Houston | E5: =VLOOKUP(A5,sf!A:E, 5, FALSE) -> TX | F5: 29.767073 | G5: -95.40908 | H5: 2737.8323 | I5: 153 | J5: 3
A6: -ORSSwLU60SID0UlE-a1 | B6: The BAR – on Dolores | C6: =VLOOKUP(A6,sf!A:C, 3, FALSE) -> Entertainment|Casual Dining | D6: San Francisco | E6: =VLOOKUP(A6,sf!A:E, 5, FALSE) -> CA | F6: 37.74373 | G6: -122.42465 | H6: 3024.1415 | I6: 169 | J6: 2
A7: -MrOD9UGCxMw0Flu5Tkt | B7: Ray’s Hideaway | C7: =VLOOKUP(A7,sf!A:C, 3, FALSE) -> Entertainment|Casual Dining | D7: Miami | E7: =VLOOKUP(A7,sf!A:E, 5, FALSE) -> FL | F7: 26.683874 | G7: -80.24728 | H7: 4971.9959 | I7: 222 | J7: 5
A8: -ODwazPotoKhGN5JhZrZ | B8: Big Easy Saloon - Kingsbury | C8: =VLOOKUP(A8,sf!A:C, 3, FALSE) -> Entertainment|Casual Dining | D8: Other | E8: =VLOOKUP(A8,sf!A:E, 5, FALSE) -> TX | F8: 29.648912 | G8: -97.829083 | H8: 3686.2317 | I8: 206 | J8: 4
A9: -Nwpq2aDKk4C6Dnowosd | B9: Wings 'N More | C9: =VLOOKUP(A9,sf!A:C, 3, FALSE) -> Entertainment|Casual Dining | D9: Austin | E9: =VLOOKUP(A9,sf!A:E, 5, FALSE) -> TX | F9: 30.424098 | G9: -97.669644 | H9: 2845.1982 | I9: 159 | J9: 3
A10: -Nz4qk-X3STUuhZVjQW7 | B10: X's & O's Sports Bar | C10: =VLOOKUP(A10,sf!A:C, 3, FALSE) -> Entertainment|Bars | D10: Chicago | E10: =VLOOKUP(A10,sf!A:E, 5, FALSE) -> IL | F10: 41.747473 | G10: -87.814689 | H10: 9626.9832 | I10: 292 | J10: 3
A11: -O5sQuxBEF-KjSyzE38g | B11: Hogg Daddy's | C11: =VLOOKUP(A11,sf!A:C, 3, FALSE) -> Entertainment|Bars | D11: Tampa Bay | E11: =VLOOKUP(A11,sf!A:E, 5, FALSE) -> FL | F11: 27.966462 | G11: -82.822945 | H11: 6084.0717 | I11: 340 | J11: 4
A12: -O4vKUnAFcZgZPrmFDss | B12: Red Pepper Taqueria - Dunwoody | C12: =VLOOKUP(A12,sf!A:C, 3, FALSE) -> Entertainment|Casual Dining | D12: Atlanta | E12: =VLOOKUP(A12,sf!A:E, 5, FALSE) -> GA | F12: 33.927577 | G12: -84.336637 | H12: 5815.6568 | I12: 325 | J12: 4
A13: -Me68kpYuJvSn-sGCagD | B13: Mis-Cue Lounge | C13: =VLOOKUP(A13,sf!A:C, 3, FALSE) -> Entertainment|Bars | D13: Miami | E13: =VLOOKUP(A13,sf!A:E, 5, FALSE) -> FL | F13: 26.181712 | G13: -80.133923 | H13: 9500.673 | I13: 229 | J13: 3
A14: -NJkG6GIsNDls2Ozq1nX | B14: My Bar | C14: =VLOOKUP(A14,sf!A:C, 3, FALSE) -> Entertainment|Bars | D14: San Antonio | E14: =VLOOKUP(A14,sf!A:E, 5, FALSE) -> TX | F14: 29.490701 | G14: -98.572418 | H14: 3463.2381 | I14: 149 | J14: 2
... A419: -NTV6LXnJVWDBiKxsrbf | B419: One Pocha | C419: =VLOOKUP(A419,sf!A:C, 3, FALSE) -> Entertainment|Casual Dining | D419: San Antonio | E419: =VLOOKUP(A419,sf!A:E, 5, FALSE) -> TX | F419: 29.570923 | G419: -98.327367 | H419: 21.619962 | I419: 1 | J419: 1
G420: TOTAL | H420: =SUM(H3:H419) -> 1879550.2 | I420: =SUM(I3:I419) -> 81366
A421: RETAIL
A422: Account Name | B422: Firebase ID | C422: IAB | D422: state | E422: Installed Screens | F422: lat | G422: long | H422: impressions | I422: market | J422: plays
A423: Corner Stop 11580 Chimney Rock Rd | B423: -O6wjgIqydnGt6LE6Tbf | C423: Retail|Convenience Stores | D423: TX | E423: 1 | F423: 29.654098 | G423: -95.480438 | H423: 1419.84 | I423: Houston | J423: 544
A424: Mini Mart Food Store - 3312 Pepperell Pkwy #6029 | B424: -OJykuRPLLBucBE0UoLA | C424: Retail|Convenience Stores | D424: AL | E424: 1 | F424: 32.634369 | G424: -85.42805 | H424: 1038.96 | I424: Other | J424: 481
A425: Speedy Stop - 2264 S Ww White Rd | B425: -OOOZfhmWJIMecf2xEew | C425: Retail|Convenience Stores | D425: TX | E425: 1 | F425: 29.389777 | G425: -98.404167 | H425: 838.11 | I425: San Antonio | J425: 273
A426: Mini Food Mart - 1208 Joe Frank Harris Parkway Southeast | B426: -OJ-ywTuWDXOR-vjK7zg | C426: Retail|Convenience Stores | D426: GA | E426: 2 | F426: 34.20428 | G426: -84.807298 | H426: 3384.61 | I426: Atlanta | J426: 1131
A427: BP (2 WAY) - 16401 W Greenfield Av | B427: -OHe1Ex-OCm9_J_9beSs | C427: Retail|Convenience Stores | D427: WI | E427: 1 | F427: 43.016528 | G427: -88.117531 | H427: 1621.83 | I427: Other | J427: 546
A428: McE's Vapor Lounge (2722 Sudderth Dr Suite C) | B428: -ODmR600BysZW9yLXs-0 | C428: Retail|Dispensaries | D428: NM | E428: 1 | F428: 33.332731 | G428: -105.67774 | H428: 2179.13 | I428: Other | J428: 393
A429: Perry Hill Package Store (1113 Perry Hill Road) | B429: -ODvghsInExUkKUnCwf3 | C429: Retail|Convenience Stores | D429: AL | E429: 2 | F429: 32.36453 | G429: -86.243715 | H429: 2164.52 | I429: Other | J429: 1060
A430: BP Pantry 41 Pewaukee Lake | B430: -OHdrvX7zz1rSmqLRBYX | C430: Retail|Convenience Stores | D430: WI | E430: 2 | F430: 43.068002 | G430: -88.277117 | H430: 3049.66 | I430: Other | J430: 1097
A431: Eagle Mart - 3701 Highland Dr | B431: -OM8yfoSBrvyLlKIBPzV | C431: Retail|Convenience Stores | D431: UT | E431: 1 | F431: 40.69109 | G431: -111.8466 | H431: 1094.39 | I431: Other | J431: 437
A432: Discount Liquor - 311 Aveue G | B432: -OJ4LkxAm6P0f24wOVq0 | C432: Retail|Liquor Stores | D432: IL | E432: 1 | F432: 41.78921 | G432: -89.706642 | H432: 12 | I432: Other | J432: 12
A433: Apollo Superette - 1025 4th St SE | B433: -OSUaXXa2kSl2iPLDPUH | C433: Retail|Convenience Stores | D433: MN | E433: 1 | F433: 44.019647 | G433: -92.449232 | H433: 325.2 | I433: Other | J433: 271
A434: Pit's Smoke Shop & Novelties - 251 Oklahoma 33 | B434: -OJQFZ0QhYR-y0cXyQIj | C434: Retail|Dispensaries | D434: OK | E434: 1 | F434: 36.115409 | G434: -97.066634 | H434: 1565.33 | I434: Other | J434: 548
... A825: Fast Eddie's Valero - 11801 Hwy 99 | B825: -OM9-b7gDx8rJLOWLaYj | C825: Retail|Convenience Stores | D825: WA | E825: 1 | F825: 47.890463 | G825: -122.25684 | H825: 682.72 | I825: Other | J825: 181
G826: TOTAL | H826: =SUM(H423:H825) -> 943323.74 | J826: =SUM(J423:J825) -> 257430

Sheet Creative Level Data
A1: BARS/RESTAURANT
A2: slideId | B2: slideName | C2: imageName | D2: impressions | E2: plays
A3: -OYrg9wHWxhr1xQxArVJ | B3: Betonline - August Ncaa Ad.mp4 | C3: 1756502316530-Betonline - August Ncaa Ad.mp4 | D3: 177196.35 | E3: 7579
A4: -Ob4m-EbQs8mu_fqwfC2 | B4: Justin herbert - BO AD.mp4 | C4: 1759959978415-Justin herbert - BO AD.mp4 | D4: 56055.209 | E4: 2087
A5: -Ob4m4_tjIaOwngh7j8g | B5: Justin herbert - BO AD.mp4 | C5: 1759960001567-Justin herbert - BO AD.mp4 | D5: 122349.18 | E5: 6020
A6: -OcBpRtGjyR0gomk9Dw3 | B6: NBA_WK43_Betonline.mp4 | C6: 1761151924886-NBA_WK43_Betonline.mp4 | D6: 739630.17 | E6: 31768
A7: -Oe2SWhz1Oyd0Ufz_DQS | B7: BetOnline Temp.mp4 | C7: 1763142230983-BetOnline Temp.mp4 | D7: 306872.92 | E7: 12878
A8: -OewcZVPYNZ3TRByIr7C | B8: Untitled design (2).mp4 | C8: 1764101500393-Untitled design (2).mp4 | D8: 75823.506 | E8: 3799
A9: -OfWSG3bF_304ygD3AvZ | B9: BetOnline Dec2 Creative NFL.mp4 | C9: 1764719131691-BetOnline Dec2 Creative NFL.mp4 | D9: 27066.296 | E9: 1362
A10: -OfWUT9oVuhDZjngSim7 | B10: BetOnline Dec2 Creative NFL.mp4 | C10: 1764719709734-BetOnline Dec2 Creative NFL.mp4 | D10: 131796.15 | E10: 5043
A11: -OfkKdj1A9bPjOiLMVsa | B11: NFL - Thru Mon.mp4 | C11: 1764968794755-NFL - Thru Mon.mp4 | D11: 74197.641 | E11: 3502
A12: -OfkKgRUWKn5hPkKOKLW | B12: CFB - Thru Sat.mp4 | C12: 1764968805970-CFB - Thru Sat.mp4 | D12: 48190.788 | E12: 2196
A13: -Og-BfhSQH9JKTteTDSY | B13: BetOnline New CFB OH:IN Creative 12:8.mp4 | C13: 1765234876202-BetOnline New CFB OH:IN Creative 12:8.mp4 | D13: 83016.578 | E13: 3416
A14: -OgJHnMUJW6R8k2dpV0w | B14: BOL NFL Dec12-15.mp4 | C14: 1765572027353-BOL NFL Dec12-15.mp4 | D14: 37355.355 | E14: 1716
A15: total | D15: =SUM(D3:D14) -> 1879550.2 | E15: =SUM(E3:E14) -> 81366
A16: RETAIL
A17: slideId | B17: slideName | C17: imageName | D17: impressions | E17: plays
A18: -OYr_M4Gqrx5eTdGGAON | B18: Betonline - August Ncaa Ad.mp4 | C18: 1756500528025-Betonline - August Ncaa Ad.mp4 | D18: 23911.14 | E18: 6402
A19: -Oauw_dhjlDqBy-VVrYK | B19: Justin herbert - BO AD.mp4 | C19: 1759778201590-Justin herbert - BO AD.mp4 | D19: 148307.65 | E19: 39172
A20: -Ob4oFBtP6mXXLKlVJZw | B20: Justin herbert - BO AD.mp4 | C20: 1759960570991-Justin herbert - BO AD.mp4 | D20: 2.22 | E20: 1
A21: -Ob4oJII28aMgiWTRogc | B21: Justin herbert - BO AD.mp4 | C21: 1759960587921-Justin herbert - BO AD.mp4 | D21: 2.2 | E21: 1
A22: -Ob4oXNY2JbC_TYAuN_C | B22: Justin herbert - BO AD.mp4 | C22: 1759960645421-Justin herbert - BO AD.mp4 | D22: 2.74 | E22: 1
A23: -Ob4oZUpQPOEXwgHi2Lw | B23: Justin herbert - BO AD.mp4 | C23: 1759960653786-Justin herbert - BO AD.mp4 | D23: 9315.69 | E23: 2507
A24: -Ob4onZxLd8AzmYolkLi | B24: Justin herbert - BO AD.mp4 | C24: 1759960715573-Justin herbert - BO AD.mp4 | D24: 1.63 | E24: 1
A25: -OcBqC5aXielx9xFB5NR | B25: NBA_WK43_Betonline.mp4 | C25: 1761152122631-NBA_WK43_Betonline.mp4 | D25: 686039.14 | E25: 188918
A26: -Oe2SI9uqN3o7eGY_3mo | B26: BetOnline Temp.mp4 | C26: 1763142221928-BetOnline Temp.mp4 | D26: 36612.65 | E26: 9832
A27: -OewcfMgBEYwxwSpP1kU | B27: Untitled design (2).mp4 | C27: 1764101512032-Untitled design (2).mp4 | D27: 9231.94 | E27: 2534
A28: -OfWTjsFgf8GztozU-rz | B28: BetOnline Dec2 Creative NFL.mp4 | C28: 1764719520540-BetOnline Dec2 Creative NFL.mp4 | D28: 17444.75 | E28: 4681
A29: -OfkJUV1Wg1qpZumkjgE | B29: NFL - Thru Mon.mp4 | C29: 1764968490785-NFL - Thru Mon.mp4 | D29: 4886.15 | E29: 1296
... A32: -OgJH09Y2s9srjSwNHbZ | B32: BOL NFL Dec12-15.mp4 | C32: 1765571821875-BOL NFL Dec12-15.mp4 | D32: 548.52 | E32: 164
A33: total | D33: =SUM(D18:D32) -> 943323.74 | E33: =SUM(E18:E32) -> 257430

Sheet State Level Data
A1: BARS/RESTAURANT
A2: state | B2: impressions | C2: plays | D2: spend
A3: AZ | B3: 296503.53 | C3: 9066 | D3: 1729.73
A4: CA | B4: 374718.2 | C4: 20854 | D4: 3902.98
A5: FL | B5: 358183.57 | C5: 16986 | D5: 3537.07
A6: GA | B6: 219462.74 | C6: 7885 | D6: 1519.06
A7: IL | B7: 200724.47 | C7: 7990 | D7: 1751.9
A8: TX | B8: 429957.65 | C8: 18585 | D8: 3359.66
A9: total | B9: =SUM(B3:B8) -> 1879550.2 | C9: =SUM(C3:C8) -> 81366 | D9: 15806
A11: RETAIL
A12: state | B12: impressions | C12: plays | D12: spend
A13: AL | B13: 31412.5 | C13: 6909 | D13: 169.35
A14: AZ | B14: 41725.55 | C14: 9427 | D14: 229.84
A15: CA | B15: 119599.03 | C15: 31129 | D15: 786.29
A16: DC | B16: 8503.72 | C16: 1636 | D16: 36.29
A17: DE | B17: 15029.5 | C17: 2159 | D17: 96.77
A18: FL | B18: 82029.08 | C18: 25925 | D18: 798.39
A19: GA | B19: 59790.02 | C19: 20954 | D19: 495.97
A20: IL | B20: 81544.47 | C20: 22966 | D20: 616.94
A21: MN | B21: 20350.01 | C21: 5501 | D21: 133.06
A22: MO | B22: 22154.95 | C22: 6819 | D22: 181.45
A23: MS | B23: 13190.48 | C23: 3174 | D23: 72.58
A24: MT | B24: 669.51 | C24: 519 | D24: 12.1
... A33: WI | B33: 51124.85 | C33: 14844 | D33: 375
A34: Totals | B34: =SUM(B13:B33) -> 943323.74 | C34: =SUM(C13:C33) -> 257430 | D34: =SUM(D13:D33) -> 6737.91

Sheet Spend By Day
A1: BARS/RESTAURANT
A2: date | B2: impressions | C2: plays | D2: spend
A3: 45992 | B3: 128472.47 | C3: 5356 | D3: 1535.48
A4: 45993 | B4: 76594.819 | C4: 2995 | D4: 112.9
A5: 45994 | B5: 78687.693 | C5: 2893 | D5: 112.9
A6: 45995 | B6: 117969.98 | C6: 5022 | D6: 1535.48
A7: 45996 | B7: 167765.32 | C7: 7562 | D7: 1535.48
A8: 45997 | B8: 181307.35 | C8: 8274 | D8: 1535.48
A9: 45998 | B9: 177417.5 | C9: 7922 | D9: 1535.48
A10: 45999 | B10: 143654.28 | C10: 6020 | D10: 1535.48
A11: 46000 | B11: 74618.158 | C11: 2916 | D11: 112.9
A12: 46001 | B12: 77757.116 | C12: 2840 | D12: 112.9
A13: 46002 | B13: 129573.3 | C13: 5589 | D13: 1535.48
A14: 46003 | B14: 180996.4 | C14: 8206 | D14: 1535.48
... A16: 46005 | B16: 178372.37 | C16: 8133 | D16: 1535.48
A17: total | B17: =SUM(B3:B16) -> 1879550.2 | C17: =SUM(C3:C16) -> 81366 | D17: =SUM(D3:D16) -> 15806.4
A19: RETAIL
A20: date | B20: impressions | C20: plays | D20: spend
A21: 45992 | B21: 62217.78 | C21: 16729 | D21: 691.24424
A22: 45993 | B22: 33296.48 | C22: 8854 | D22: 48.387097
A23: 45994 | B23: 33622.86 | C23: 8901 | D23: 48.387097
A24: 45995 | B24: 35980.88 | C24: 9370 | D24: 691.24424
A25: 45996 | B25: 69257.09 | C25: 18373 | D25: 691.24424
A26: 45997 | B26: 68835.59 | C26: 18233 | D26: 691.24424
A27: 45998 | B27: 67569.01 | C27: 18243 | D27: 691.24424
A28: 45999 | B28: 61601.36 | C28: 16487 | D28: 617.63
A29: 46000 | B29: 80114.16 | C29: 21568 | D29: 48.387097
A30: 46001 | B30: 80542.31 | C30: 21429 | D30: 48.387097
A31: 46002 | B31: 78542.96 | C31: 21226 | D31: 617.63
A32: 46003 | B32: 79417.25 | C32: 22758 | D32: 617.63
... A34: 46005 | B34: 95252.91 | C34: 27406 | D34: 617.63
A35: Totals | B35: =SUM(B21:B34) -> 943323.74 | C35: =SUM(C21:C34) -> 257430 | D35: =SUM(D21:D34) -> 6737.9196

Sheet sf
A1: Firebase Id | B1: IAB Venue Type | C1: Vistar Venue Type | D1: Account Name | E1: Shipping State/Province | F1: Account ID | G1: Revenue Share Percentage | H1: DMA
A2: -Lm89I_2XS4Taz6KQV7u | B2: Entertainment | Restaurant and Bar | C2: Entertainment|Casual Dining | D2: Fionns Grant Park | E2: MB | F2: 001OG000016zOVF | G2: 15 | H2: WINNIPEG
A3: -N7vB4glPqShJ1qEHZau | B3: Entertainment | Restaurant and Bar | C3: Entertainment|Casual Dining | D3: Taiv HQ | E3: MB | F3: 0018V00002RiBln | G3: 15 | H3: WINNIPEG
A4: -NVfdTVT2B7L9M4DW-uK | B4: Entertainment | Restaurant and Bar | C4: Entertainment|Casual Dining | D4: Paddy Kelly's | E4: MA | F4: 001OG000019i3Xb | G4: 15 | H4: BOSTON (MANCHESTER)
A5: -O9M57k5rIUKvFdpgX4O | B5: Entertainment | Restaurant and Bar | C5: Entertainment|Casual Dining | D5: Horus Cafe | E5: NY | F5: 0018V00002f5kWa | G5: 15 | H5: NEW YORK
A6: -O9WJ2SlG98VV_CKfYaP | B6: Entertainment | Restaurant and Bar | C6: Entertainment|Casual Dining | D6: Shotzee's Bar And Grill | E6: TX | F6: 0018V00002hB8TI | G6: 15 | H6: DALLAS - FT. WORTH
A7: -O_CyzMLiCsHEy0Fka16 | B7: Entertainment | Restaurant and Bar | C7: Entertainment|Casual Dining | D7: Wonder Bar | E7: NJ | F7: 001OG000016yDuO | G7: 15 | H7: PHILADELPHIA
A8: -O_Czs_45eSb_6t3Phb5 | B8: Entertainment | Restaurant and Bar | C8: Entertainment|Casual Dining | D8: Dooney's Pub Voorhees | E8: NJ | F8: 001OG000018R0na | G8: 15 | H8: PHILADELPHIA
A9: -O_D-Sxw48a26HdIwQug | B9: Entertainment | Restaurant and Bar | C9: Entertainment|Casual Dining | D9: Dooney's Pub Delran | E9: NJ | F9: 001OG000018Qt99 | G9: 15 | H9: PHILADELPHIA
A10: -O_D1YnHKYI4O12HfWo- | B10: Entertainment | Restaurant and Bar | C10: Entertainment|Casual Dining | D10: Patrizia's Taverna | E10: NY | F10: 001OG000017J7yw | G10: 15 | H10: NEW YORK
A11: -O_Ddul1kBg8t-1ZI3CW | B11: Entertainment | Restaurant and Bar | C11: Entertainment|Casual Dining | D11: Pikes Cinema Bar and Grill | E11: MD | F11: 001OG000016ueKm | G11: 15 | H11: BALTIMORE
A12: -O_DgPsRfCybGjUKPONk | B12: Entertainment | Restaurant and Bar | C12: Entertainment|Bars | D12: Del Webb Lakewood Ranch Lake House | E12: FL | F12: 001OG000018YsSH | G12: 15 | H12: TAMPA - ST. PETE (SARASOTA)
A13: -O_DgSV0jE3wCUe-w7W3 | B13: Entertainment | Restaurant and Bar | C13: Entertainment|Casual Dining | D13: Element Restaurant & Bar | E13: NJ | F13: 001OG000018R0KE | G13: 15 | H13: NEW YORK
... A125: -ObY8tmwM7Ao_GTe8Q3v | B125: Entertainment | Restaurant and Bar | C125: Entertainment|Casual Dining | D125: Cagney's | E125: MA | F125: 001OG000010cAvU | G125: 15 | H125: BOSTON (MANCHESTER)
A126: -ObYYBUZCzBcK8jRU-CW | B126: Entertainment | Restaurant and Bar | C126: Entertainment|Casual Dining | D126: Shell Shack HO | E126: TX | F126: 001OG00001Abv4H | H126: DALLAS - FT. WORTH
A127: -ObZ29cn65HHsRWuOGVN | B127: Entertainment | Restaurant and Bar | C127: Entertainment|Casual Dining | D127: Village Tavern | Bar & grill | E127: MA | F127: 001OG000010c6bW | G127: 15 | H127: BOSTON (MANCHESTER)
A128: -ObZJLWbRo16k9hzWNvD | B128: Entertainment | Restaurant and Bar | C128: Entertainment|Bars | D128: Water's Edge Bar & Grill | E128: MO | F128: 001OG000019l7yB | G128: 15 | H128: KANSAS CITY
A129: -ObZK1Kr4KB3y8z3PA2o | B129: Entertainment | Restaurant and Bar | C129: Entertainment|Bars | D129: Edge on 7 Bar & Grill | E129: MO | F129: 001OG000019lKVY | G129: 15 | H129: KANSAS CITY
A130: -Oc1v_L4RIPb3uzdQmCZ | B130: Entertainment | Restaurant and Bar | C130: Entertainment|Casual Dining | D130: Hermosa Brewing Company - Hermosa Beach | E130: CA | F130: 001OG00000uoXWl | G130: 15 | H130: LOS ANGELES
A131: -Oc1yXXkafD_XW1CiDyA | B131: Entertainment | Restaurant and Bar | C131: Entertainment|Casual Dining | D131: Hermosa Brewing Company Torrance | E131: CA | F131: 001OG00000uoP0m | G131: 15 | H131: LOS ANGELES
A132: -Oc2J1u8VZRIs_sQaFcA | B132: Entertainment | Restaurant and Bar | C132: Entertainment|Bars | D132: Olde Town Tavern and Grill - Ralston | E132: CO | F132: 001OG000019lLro | G132: 15 | H132: DENVER
A133: -Oc6d7Dzz-k3Yy3FMOyH | B133: Entertainment | Restaurant and Bar | C133: Entertainment|Bars | D133: The Bar West Plaza | E133: MO | F133: 001OG000019lK4J | G133: 15 | H133: KANSAS CITY
A134: -Oc7Cb5Ig_MFr74FCduV | B134: Entertainment | Restaurant and Bar | C134: Entertainment|Casual Dining | D134: Orangedale Lounge | E134: AZ | F134: 001OG00001AJCOz | G134: 15 | H134: PHOENIX (PRESCOTT)
A135: -Oc7PkVYWXh1T5-OHyTK | B135: Entertainment | Restaurant and Bar | C135: Entertainment|Casual Dining | D135: Turtle Bay | E135: LA | F135: 001OG0000181s1H | G135: 15 | H135: NEW ORLEANS
A136: -OcbaSd8n289b4TF6bwi | B136: Entertainment | Restaurant and Bar | C136: Entertainment|Casual Dining | D136: Hook & Reel Cajun Seafood & Bar - Denver | E136: CO | F136: 001OG00001ARP5i | G136: 15 | H136: DENVER
A137: -OcBcyjKzkR0o3scyAOw | B137: Entertainment | Restaurant and Bar | C137: Entertainment|Casual Dining | D137: Ott's Greentop | E137: NJ | F137: 001OG000018QyGl | G137: 15 | H137: PHILADELPHIA
A138: -OcBdoq0GN-c4bKBuS1h | B138: Entertainment | Restaurant and Bar | C138: Entertainment|Casual Dining | D138: Braddock's Tavern | E138: NJ | F138: 001OG000018Qt96 | G138: 15 | H138: PHILADELPHIA
... A147: -OckiVL3ZeUAhqdHptyI | B147: Entertainment | Restaurant and Bar | C147: Entertainment|Casual Dining | D147: PlayMakers Sports Bar & Grill | E147: MO | F147: 001OG00001AGYQQ | G147: 15 | H147: ST. LOUIS
A148: -OckkHIwHwesl_Alpw5g | B148: Entertainment | Restaurant and Bar | C148: Entertainment|Casual Dining | D148: Drake's Paddock Shops | E148: KY | F148: 001OG00001ANxsM | H148: LOUISVILLE
A149: -OckqNFu8a3f2wm3tfi5 | B149: Entertainment | Restaurant and Bar | C149: Entertainment|Casual Dining | D149: Timber Creek Grill | E149: MO | F149: 001OG00001AGdME | G149: 15 | H149: ST. LOUIS
A150: -OckZnznwPETT83dXyxq | B150: Entertainment | Restaurant and Bar | C150: Entertainment|Bars | D150: Gibsons Bar & Steakhouse (Rosemont) | E150: IL | F150: 0018V00002fiUTi | G150: 15 | H150: CHICAGO
A151: -Ocl3YURzB3hqWpNCihW | B151: Entertainment | Restaurant and Bar | C151: Entertainment|Casual Dining | D151: Oskar Blues Grill & Brew - Colorado Springs | E151: CO | F151: 001OG00001B4w8E | G151: 15 | H151: COLORADO SPRINGS - PUEBLO
A152: -OclfIL7DihFnUotOLl- | B152: Entertainment | Restaurant and Bar | C152: Entertainment|Casual Dining | D152: The Rally Sports Bar & Grille | E152: RI | F152: 001OG00001B5Kgn | G152: 15 | H152: PROVIDENCE - NEW BEDFORD
A153: -OclfiT7G9-yMrOuFRe3 | B153: Entertainment | Restaurant and Bar | C153: Entertainment|Casual Dining | D153: O'Rourkes Bar & Grill | E153: RI | F153: 001OG00001B5LmX | G153: 15 | H153: PROVIDENCE - NEW BEDFORD
A154: -OclIv76luGq0F9mIcjN | B154: Entertainment | Restaurant and Bar | C154: Entertainment|Casual Dining | D154: 1356 Public House | E154: MO | F154: 001OG00001AGc6R | G154: 15 | H154: ST. LOUIS
A155: -OcllBz-_Oq2RcqRRPJ1 | B155: Entertainment | Restaurant and Bar | C155: Entertainment|Casual Dining | D155: Birch & Bay Roofdeck Coastal Kitchen | E155: RI | F155: 001OG00001B5Hr0 | G155: 15 | H155: PROVIDENCE - NEW BEDFORD
A156: -Oclp0GbFp15zpdGNvHe | B156: Entertainment | Restaurant and Bar | C156: Entertainment|Casual Dining | D156: Locales Taco + Tequila Bar | E156: CO | F156: 001OG00001AQT4x | G156: 15 | H156: DENVER
A157: -OcN4z_w5d-HtdCImEyB | B157: Entertainment | Restaurant and Bar | C157: Entertainment|Bars | D157: Jake's Roadhouse | E157: CO | F157: 001OG000019lLOR | G157: 15 | H157: DENVER
A158: -Ocqbxj99WaFEDsmBHWs | B158: Entertainment | Restaurant and Bar | C158: Entertainment|Casual Dining | D158: Lazy Dog Restaurant & Bar - Garland | E158: TX | F158: 001OG00001A9SZo | H158: DALLAS - FT. WORTH
A159: -Ocqc15Eq3BT-LtKoOQN | B159: Entertainment | Restaurant and Bar | C159: Entertainment|Casual Dining | D159: Lazy Dog Restaurant & Bar - Irvine | E159: CA | F159: 001OG00001A9SZ9 | H159: LOS ANGELES
...
