Workbook

Sheet Venue Level Data
A1: clientId | B1: venue | C1: venue type | D1: market | E1: state | F1: lat | G1: long | H1: impressions | I1: plays | J1: ScreensAtLocation
A2: -OVEr3t2wtyBAiMu31P4 | B2: LandLubber's Raw Bar & Grill | C2: =VLOOKUP(A2,salesforce!A:E, 3, FALSE) -> Entertainment|Casual Dining | D2: Miami | E2: =VLOOKUP(A2, salesforce!A:E, 5, FALSE) -> FL | F2: 26.148384 | G2: -80.270295 | H2: 98418.807 | I2: 5500 | J2: 60
A3: -ORCEhKeRDd7_YyPVef1 | B3: Surf Lounge | C3: =VLOOKUP(A3,salesforce!A:E, 3, FALSE) -> Entertainment|Casual Dining | D3: San Francisco | E3: =VLOOKUP(A3, salesforce!A:E, 5, FALSE) -> CA | F3: 37.651267 | G3: -122.49155 | H3: 210276.26 | I3: 11751 | J3: 3
A4: -NV0cP-3nGPweG7gqqlU | B4: What's It To Ya Lounge | C4: =VLOOKUP(A4,salesforce!A:E, 3, FALSE) -> Entertainment|Bars | D4: San Antonio | E4: =VLOOKUP(A4, salesforce!A:E, 5, FALSE) -> TX | F4: 29.489752 | G4: -98.598586 | H4: 9767.5094 | I4: 1768 | J4: 3
A5: -OSQucWejPvs1J_lg-yj | B5: Berry Fresh Cafe (Palm beach Gardens) | C5: =VLOOKUP(A5,salesforce!A:E, 3, FALSE) -> Entertainment|Casual Dining | D5: Miami | E5: =VLOOKUP(A5, salesforce!A:E, 5, FALSE) -> FL | F5: 26.845849 | G5: -80.059037 | H5: 304.20359 | I5: 17 | J5: 2
A6: -NAbL2mCCHVpvNp1_VIl | B6: Crab Shack on the Cotee River | C6: =VLOOKUP(A6,salesforce!A:E, 3, FALSE) -> Entertainment|Casual Dining | D6: Tampa Bay | E6: =VLOOKUP(A6, salesforce!A:E, 5, FALSE) -> FL | F6: 28.269489 | G6: -82.724308 | H6: 8065.2755 | I6: 391 | J6: 3
A7: -O4vKUnAFcZgZPrmFDss | B7: Red Pepper Taqueria - Dunwoody | C7: =VLOOKUP(A7,salesforce!A:E, 3, FALSE) -> Entertainment|Casual Dining | D7: Atlanta | E7: =VLOOKUP(A7, salesforce!A:E, 5, FALSE) -> GA | F7: 33.927577 | G7: -84.336637 | H7: 104968.13 | I7: 5866 | J7: 4
A8: -O4qYDyxiZgO7sBeoWOD | B8: SportsTime2 Bar & Grille | C8: =VLOOKUP(A8,salesforce!A:E, 3, FALSE) -> Entertainment|Bars | D8: Atlanta | E8: =VLOOKUP(A8, salesforce!A:E, 5, FALSE) -> GA | F8: 33.942015 | G8: -84.269524 | H8: 24515.23 | I8: 1370 | J8: 4
A9: -NZCoeZGfmH63k3bdcjI | B9: The Juicy Seafood Hallandale Beach FL | C9: =VLOOKUP(A9,salesforce!A:E, 3, FALSE) -> Entertainment|Casual Dining | D9: Miami | E9: =VLOOKUP(A9, salesforce!A:E, 5, FALSE) -> FL | F9: 25.984587 | G9: -80.133102 | H9: 1648.4232 | I9: 606 | J9: 6
A10: -OPHV6VfWgjffHguhjZj | B10: The Sportsmen's Lounge | C10: =VLOOKUP(A10,salesforce!A:E, 3, FALSE) -> Entertainment|Bars | D10: San Francisco | E10: =VLOOKUP(A10, salesforce!A:E, 5, FALSE) -> CA | F10: 37.32963 | G10: -121.96276 | H10: 28577.243 | I10: 1597 | J10: 4
A11: -NJ63P4wpMOPu6Ez5-kr | B11: Charlie Brown's Neighourhood Bar and Grill | C11: =VLOOKUP(A11,salesforce!A:E, 3, FALSE) -> Entertainment|Casual Dining | D11: San Antonio | E11: =VLOOKUP(A11, salesforce!A:E, 5, FALSE) -> TX | F11: 29.548019 | G11: -98.461077 | H11: 1806.3486 | I11: 704 | J11: 7
A12: -OP7Z9IbbtmdBBOnQUk- | B12: Hidden Tap And Barrel Palo Alto | C12: =VLOOKUP(A12,salesforce!A:E, 3, FALSE) -> Entertainment|Casual Dining | D12: San Francisco | E12: =VLOOKUP(A12, salesforce!A:E, 5, FALSE) -> CA | F12: 37.446119 | G12: -122.16108 | H12: 9645.0431 | I12: 539 | J12: 7
A13: -OSuKhhtpMuav1FiT0ze | B13: Beef 'O' Brady's - Lakewood Ranch | C13: =VLOOKUP(A13,salesforce!A:E, 3, FALSE) -> Entertainment|Casual Dining | D13: Tampa Bay | E13: =VLOOKUP(A13, salesforce!A:E, 5, FALSE) -> FL | F13: 27.48256 | G13: -82.431993 | H13: 84550.702 | I13: 4725 | J13: 5
... A162: -O1x93DPAr0Hzs0KLyle | B162: Vickery's Bar & Grill - Glenwood Park | C162: =VLOOKUP(A162,salesforce!A:E, 3, FALSE) -> Entertainment|Casual Dining | D162: Atlanta | E162: =VLOOKUP(A162, salesforce!A:E, 5, FALSE) -> GA | F162: 33.74032 | G162: -84.357396 | H162: 9591.3601 | I162: 536 | J162: 2
A163: -O5xq8ttf8dfkew70qPt | B163: Vvs restaurant and bar | C163: Entertainment|Sports Entertainment | D163: Atlanta | E163: GA | F163: 33.58474 | G163: -84.469833 | H163: 7575.4049 | I163: 156 | J163: 12
A164: -O0f111Eyqpsn6iYaIx- | B164: Christies Sports Bar | C164: =VLOOKUP(A164,salesforce!A:E, 3, FALSE) -> Entertainment|Bars | D164: Dallas | E164: =VLOOKUP(A164, salesforce!A:E, 5, FALSE) -> TX | F164: 32.823275 | G164: -96.770407 | H164: 11153.909 | I164: 160 | J164: 20
A165: -Ng-OmN3ambuQKueVl0H | B165: On Rotation Brewhouse | C165: =VLOOKUP(A165,salesforce!A:E, 3, FALSE) -> Entertainment|Casual Dining | D165: Dallas | E165: =VLOOKUP(A165, salesforce!A:E, 5, FALSE) -> TX | F165: 32.848472 | G165: -96.840402 | H165: 15031.236 | I165: 840 | J165: 3
A166: -OMwpG2f_lveERSeFHbM | B166: 2 Vinez | C166: =VLOOKUP(A166,salesforce!A:E, 3, FALSE) -> Entertainment|Casual Dining | D166: Miami | E166: =VLOOKUP(A166, salesforce!A:E, 5, FALSE) -> FL | F166: 26.935135 | G166: -80.08847 | H166: 8410.3344 | I166: 470 | J166: 2
A167: -Nrv4SrFj7JdOrAIbQIy | B167: Bon Zanmi | C167: =VLOOKUP(A167,salesforce!A:E, 3, FALSE) -> Entertainment|Casual Dining | D167: Tampa Bay | E167: =VLOOKUP(A167, salesforce!A:E, 5, FALSE) -> FL | F167: 28.055379 | G167: -82.441583 | H167: 2843 | I167: 2843 | J167: 4
A168: -ONLp1StZiWR757GgtLl | B168: First Cabin Bar | C168: =VLOOKUP(A168,salesforce!A:E, 3, FALSE) -> Entertainment|Casual Dining | D168: Los Angeles | E168: =VLOOKUP(A168, salesforce!A:E, 5, FALSE) -> CA | F168: 34.139876 | G168: -118.02942 | H168: 8052.4479 | I168: 450 | J168: 2
A169: -OJQ6nMqYmq69H-eBZzZ | B169: The Coyote Bar & Grill | C169: =VLOOKUP(A169,salesforce!A:E, 3, FALSE) -> Entertainment|Casual Dining | D169: San Diego | E169: =VLOOKUP(A169, salesforce!A:E, 5, FALSE) -> CA | F169: 33.159249 | G169: -117.35035 | H169: 7354.569 | I169: 411 | J169: 7
A170: -NNsCtpVM4In8aBRC3pZ | B170: Monster Pizza | C170: =VLOOKUP(A170,salesforce!A:E, 3, FALSE) -> Entertainment|Casual Dining | D170: Tampa Bay | E170: =VLOOKUP(A170, salesforce!A:E, 5, FALSE) -> FL | F170: 27.960534 | G170: -82.441133 | H170: 10514 | I170: 10514 | J170: 2
A171: -OOyKBQfKyxmqk4OZcRq | B171: The Chieftain Irish Pub & Restaurant | C171: =VLOOKUP(A171,salesforce!A:E, 3, FALSE) -> Entertainment|Bars | D171: San Francisco | E171: =VLOOKUP(A171, salesforce!A:E, 5, FALSE) -> CA | F171: 37.781464 | G171: -122.40529 | H171: 14064.942 | I171: 786 | J171: 2
A172: -OQkhoqF5g4WP-lGpypK | B172: Bobby G's Pizzeria | C172: =VLOOKUP(A172,salesforce!A:E, 3, FALSE) -> Entertainment|Casual Dining | D172: San Francisco | E172: =VLOOKUP(A172, salesforce!A:E, 5, FALSE) -> CA | F172: 37.871869 | G172: -122.26902 | H172: 12615.502 | I172: 705 | J172: 2
A173: -NN8gjonmznHbkKA37nB | B173: Cotee River Brewing Company | C173: =VLOOKUP(A173,salesforce!A:E, 3, FALSE) -> Entertainment|Bars | D173: Tampa Bay | E173: =VLOOKUP(A173, salesforce!A:E, 5, FALSE) -> FL | F173: 28.250024 | G173: -82.718864 | H173: 33687.977 | I173: 1795 | J173: 2
A174: -OPas6RL6oq2R6Tl8s3d | B174: Corner Bar / SoHo | C174: =VLOOKUP(A174,salesforce!A:E, 3, FALSE) -> Entertainment|Casual Dining | D174: Tampa Bay | E174: =VLOOKUP(A174, salesforce!A:E, 5, FALSE) -> FL | F174: 27.940908 | G174: -82.482809 | H174: 2719.9379 | I174: 152 | J174: 6
A175: -NdflmZuVkI-Tq99ixgc | B175: The Wildcatter | C175: =VLOOKUP(A175,salesforce!A:E, 3, FALSE) -> Entertainment|Bars | D175: Houston | E175: =VLOOKUP(A175, salesforce!A:E, 5, FALSE) -> TX | F175: 29.774007 | G175: -95.842761 | H175: 603241.55 | I175: 12223 | J175: 3
... A250: -NqnxGJtIvUd3JGx6HVm | B250: Whiskey River | C250: =VLOOKUP(A250,salesforce!A:E, 3, FALSE) -> Entertainment|Casual Dining | D250: Chicago | E250: =VLOOKUP(A250, salesforce!A:E, 5, FALSE) -> IL | F250: 42.088742 | G250: -87.798542 | H250: 11853.599 | I250: 1071 | J250: 4
A251: -NvCmJuLZqyGYVrEfZfq | B251: Aerodrome Ice Skating Complex | C251: Entertainment|Sports Entertainment | D251: Houston | E251: TX | F251: 29.962744 | G251: -95.553691 | H251: 20581.549 | I251: 921 | J251: 3
A252: -MZIpTEA77azalpQ8Qbu | B252: Patron Azteca Hollywood | C252: =VLOOKUP(A252,salesforce!A:E, 3, FALSE) -> Entertainment|Casual Dining | D252: Miami | E252: =VLOOKUP(A252, salesforce!A:E, 5, FALSE) -> FL | F252: 26.033482 | G252: -80.195822 | H252: 27102.711 | I252: 402 | J252: 2
A253: -NfLt4_0WBBWVMmOSj9W | B253: Moe's Cantina - River North | C253: =VLOOKUP(A253,salesforce!A:E, 3, FALSE) -> Entertainment|Casual Dining | D253: Chicago | E253: =VLOOKUP(A253, salesforce!A:E, 5, FALSE) -> IL | F253: 41.888988 | G253: -87.633201 | H253: 2204.2977 | I253: 417 | J253: 4
A254: -NxxWAf2h3mbnHD6YxvX | B254: Machupicchu Peruvian Cuisine | C254: =VLOOKUP(A254,salesforce!A:E, 3, FALSE) -> Entertainment|Casual Dining | D254: Miami | E254: =VLOOKUP(A254, salesforce!A:E, 5, FALSE) -> FL | F254: 25.702804 | G254: -80.369391 | H254: 4702.9223 | I254: 1854 | J254: 2
A255: -Nc8tntURqLUJlQ5gRq4 | B255: Pizzeria Aroma | C255: =VLOOKUP(A255,salesforce!A:E, 3, FALSE) -> Entertainment|Casual Dining | D255: Chicago | E255: =VLOOKUP(A255, salesforce!A:E, 5, FALSE) -> IL | F255: 41.979612 | G255: -87.660169 | H255: 8264.9708 | I255: 919 | J255: 3
A256: -O4Mh7DEd_5D_XZD8jUf | B256: Speakeasy Lounge | C256: =VLOOKUP(A256,salesforce!A:E, 3, FALSE) -> Entertainment|Bars | D256: Austin | E256: =VLOOKUP(A256, salesforce!A:E, 5, FALSE) -> TX | F256: 30.350409 | G256: -97.964715 | H256: 8804.0097 | I256: 492 | J256: 2
A257: -Nu_S72gWs8hNIka9HeE | B257: Double J Sports Bar | C257: =VLOOKUP(A257,salesforce!A:E, 3, FALSE) -> Entertainment|Bars | D257: Chicago | E257: =VLOOKUP(A257, salesforce!A:E, 5, FALSE) -> IL | F257: 41.540193 | G257: -88.161524 | H257: 134191.9 | I257: 2528 | J257: 5
A258: -OQiIkXjeEeAWSXHROZq | B258: Bowl of Fortune | C258: =VLOOKUP(A258,salesforce!A:E, 3, FALSE) -> Entertainment|Casual Dining | D258: Chicago | E258: =VLOOKUP(A258, salesforce!A:E, 5, FALSE) -> IL | F258: 42.139358 | G258: -87.953655 | H258: 45469.489 | I258: 2541 | J258: 1
A259: -OO3KDgnMGCBG9yGjQdr | B259: Whiskey Park | C259: =VLOOKUP(A259,salesforce!A:E, 3, FALSE) -> Entertainment|Bars | D259: Other | E259: =VLOOKUP(A259, salesforce!A:E, 5, FALSE) -> FL | F259: 26.165852 | G259: -81.766365 | H259: 15407.017 | I259: 861 | J259: 3
A260: -OYHYkjo-kYtsfB8iHkA | B260: Jay Dee’z Sports Grille | C260: =VLOOKUP(A260,salesforce!A:E, 3, FALSE) -> Entertainment|Casual Dining | D260: Houston | E260: =VLOOKUP(A260, salesforce!A:E, 5, FALSE) -> TX | F260: 29.90244 | G260: -96.905781 | H260: 33.064816 | I260: 5 | J260: 1
A261: -OAtc5TVt_Juk4Y1DgSN | B261: FFS - Irving Cicero Currency Exchange 4814 W Irving Park Rd | C261: =VLOOKUP(A261,salesforce!A:E, 3, FALSE) -> Financial|Banks | D261: Chicago | E261: =VLOOKUP(A261, salesforce!A:E, 5, FALSE) -> IL | F261: 41.953567 | G261: -87.748132 | H261: 8705.44 | I261: 3386 | J261: 1
A262: -OJUz-sVzUw1I88K6njP | B262: Tacos El Vaquero Arre lulu | C262: =VLOOKUP(A262,salesforce!A:E, 3, FALSE) -> Entertainment|Casual Dining | D262: Houston | E262: =VLOOKUP(A262, salesforce!A:E, 5, FALSE) -> TX | F262: 29.602435 | G262: -95.216799 | H262: 227401.13 | I262: 12708 | J262: 3
...

Sheet Creative Level Data
A1: slideId | B1: slideName | C1: imageName | D1: impressions | E1: plays
A2: -OYrg9wHWxhr1xQxArVJ | B2: Betonline - August Ncaa Ad.mp4 | C2: 1756502316530-Betonline - August Ncaa Ad.mp4 | D2: 3008307.7 | E2: 156239
A3: -OZLLO8Chtm9NllEM0hv | B3: BetOnline - August NCAA Ad (1).mp4 | C3: 1757016704350-BetOnline - August NCAA Ad (1).mp4 | D3: 450427.39 | E3: 24934
A4: -OZLZKGOk9Z8hxr65jJ_ | B4: BetOnline - BillsRavens.mp4 | C4: 1757020357704-BetOnline - BillsRavens.mp4 | D4: 425191.76 | E4: 23434
A5: -OZL__ncFXrRzVIC5Vxu | B5: BetOnline - BillsRavens.mp4 | C5: 1757020616443-BetOnline - BillsRavens.mp4 | D5: 425407.46 | E5: 23732
A6: -OZL_g6xpfAneNlzRyyu | B6: NFL Survivor Contest.mp4 | C6: 1757020695316-NFL Survivor Contest.mp4 | D6: 434832.64 | E6: 23775
A7: -OZp7YMcG0sVHyclPmuv | B7: BetOnline - NFL (DALLAS_SF)..mp4 | C7: 1757533172277-BetOnline - NFL (DALLAS_SF)..mp4 | D7: 269276.26 | E7: 14331
A8: -OZskHnYEnegQiI29PZl | B8: BetOnline - NFL (DALLASSF)..mp4 | C8: 1757593899894-BetOnline - NFL (DALLASSF)..mp4 | D8: 1328070.3 | E8: 71244
A9: -OZv1TOKN7R8Br8tnZhK | B9: bol_nfl_wk2_odds_promo_091125 (1080p).mp4 | C9: 1757632237582-bol_nfl_wk2_odds_promo_091125 (1080p).mp4 | D9: 1247412.8 | E9: 69205
A10: -OZv1dlcqPCrp4lrl59i | B10: bol_cfb_wk3_odds_promo_091125 (1080p).mp4 | C10: 1757632251359-bol_cfb_wk3_odds_promo_091125 (1080p).mp4 | D10: 1198729 | E10: 66749
A11: -Oa0NqwQK__ycepC47gQ | B11: Copy of BetOnline - NFL (DALLASSF)..mp4 | C11: 1758812497371-Copy of BetOnline - NFL (DALLASSF)..mp4 | D11: 1877039.1 | E11: 105019
A12: total | D12: =SUM(D2:D11) -> 10664694 | E12: =SUM(E2:E11) -> 578662
A13: RETAIL
A14: slideId | B14: slideName | C14: imageName | D14: impressions | E14: plays
A15: -OYr_M4Gqrx5eTdGGAON | B15: Betonline - August Ncaa Ad.mp4 | C15: 1756500528025-Betonline - August Ncaa Ad.mp4 | D15: 5786033 | E15: 1492393
A16: -OZLLVDV-CWgo8YdBzaK | B16: BetOnline - August NCAA Ad (1).mp4 | C16: 1757016683778-BetOnline - August NCAA Ad (1).mp4 | D16: 2238058 | E16: 597437
A17: -OZLZSb5uWJuop41eYWg | B17: BetOnline - BillsRavens.mp4 | C17: 1757020379300-BetOnline - BillsRavens.mp4 | D17: 2172487 | E17: 580727
A18: -OZLaBPjjwKjBROfXrDJ | B18: BetOnline - BillsRavens.mp4 | C18: 1757020789787-BetOnline - BillsRavens.mp4 | D18: 2169212 | E18: 580068
A19: -OZLaDEEFOq5EQbpbN7_ | B19: NFL Survivor Contest.mp4 | C19: 1757020853511-NFL Survivor Contest.mp4 | D19: 2159962 | E19: 577621
A20: -OZp7g-8yjaOUzBkGnTp | B20: BetOnline - NFL (DALLAS_SF)..mp4 | C20: 1757533189650-BetOnline - NFL (DALLAS_SF)..mp4 | D20: 2443811 | E20: 646978
A21: -OZskSDeS434sK4w16hP | B21: BetOnline - NFL (DALLASSF)..mp4 | C21: 1757593950113-BetOnline - NFL (DALLASSF)..mp4 | D21: 5774139 | E21: 1555206
A22: -OZv1SWQm8hw3MEdK3Up | B22: bol_nfl_wk2_odds_promo_091125 (1080p).mp4 | C22: 1757632225796-bol_nfl_wk2_odds_promo_091125 (1080p).mp4 | D22: 5882649 | E22: 1581678
A23: -OZv1XEJG8xNoL8m1S-o | B23: bol_cfb_wk3_odds_promo_091125 (1080p).mp4 | C23: 1757632247559-bol_cfb_wk3_odds_promo_091125 (1080p).mp4 | D23: 5870819 | E23: 1576606
A24: -Oa0NwAhG8iWxgizsg3v | B24: Copy of BetOnline - NFL (DALLASSF)..mp4 | C24: 1758812528255-Copy of BetOnline - NFL (DALLASSF)..mp4 | D24: 356991 | E24: 103672
A25: total | D25: 34854161 | E25: 9292386

Sheet State Level Data
A1: state | B1: impressions | C1: plays | D1: spend
A2: AZ | B2: 583657.98 | C2: 25162 | D2: 3518.05
A3: CA | B3: 1475800.8 | C3: 85314 | D3: 4213.76
A4: FL | B4: 2299765.3 | C4: 133077 | D4: 7453.85
A5: GA | B5: 758731.17 | C5: 40879 | D5: 2399.03
A6: IL | B6: 1819353.1 | C6: 85644 | D6: 6870.56
A7: TX | B7: 3727386.1 | C7: 208586 | D7: 9914.75
A8: total | B8: =SUM(B2:B7) -> 10664694 | C8: =SUM(C2:C7) -> 578662 | D8: =SUM(D1:D7) -> 34370
A9: RETAIL
A10: state | B10: impressions | C10: plays | D10: spend
A11: AL | B11: 1304240 | C11: 201583 | D11: 283
A12: AZ | B12: 1086396 | C12: 258130 | D12: 632
A13: CA | B13: 3978064 | C13: 1036887 | D13: 1460
A14: DC | B14: 137823 | C14: 31168 | D14: 131
A15: DE | B15: 717254 | C15: 84464 | D15: 283
A16: FL | B16: 4228682 | C16: 1123287 | D16: 1613
A17: GA | B17: 1866470 | C17: 684243 | D17: 1024
A18: ID | B18: 64513 | C18: 41091 | D18: 87
A19: IL | B19: 2479900 | C19: 733805 | D19: 1220
A20: MN | B20: 651632 | C20: 145609 | D20: 436
A21: MO | B21: 932373 | C21: 260738 | D21: 349
A22: MS | B22: 640686 | C22: 111635 | D22: 349
... A33: total | B33: 34854161 | C33: 9292386 | D33: 14730

Sheet Spend By Day
A1: date | C1: impressions | D1: plays | E1: spend
A2: 45901 | B2: MOnday | C2: 522415.21 | D2: 26503 | E2: 1166.6666
A3: 45902 | B3: Tuesday | C3: 756988.22 | D3: 40050 | E3: 1166.6666
A4: 45903 | B4: Wednesday | C4: 760708.79 | D4: 39496 | E4: 1166.6666
A5: 45904 | B5: Thursday | C5: 472757.86 | D5: 24726 | E5: 1166.6666
A6: 45905 | B6: Friday | C6: 346932.34 | D6: 18709 | E6: 1166.6666
A7: 45906 | B7: Saturday | C7: 373352.7 | D7: 20137 | E7: 1166.6666
A8: 45907 | B8: Sunday | C8: 357573.78 | D8: 19548 | E8: 1166.6666
A9: 45908 | B9: Monday | C9: 304613.49 | D9: 16175 | E9: 1166.6666
A10: 45909 | B10: Tuesday | C10: 360395.8 | D10: 19463 | E10: 1166.6666
A11: 45910 | B11: Wednesday | C11: 316206.24 | D11: 17992 | E11: 1166.6666
A12: 45911 | B12: Thursday | C12: 384552.65 | D12: 20794 | E12: 1166.6666
A13: 45912 | B13: Friday | C13: 317947.84 | D13: 17549 | E13: 1166.6666
... A31: 45930 | B31: Tuesday | C31: 197551.03 | D31: 11148 | E31: 116.66666
A32: total | C32: =SUM(C2:C31) -> 10664694 | D32: =SUM(D2:D31) -> 578662 | E32: =SUM(E2:E31) -> 34369.998
A33: RETAIL
A34: date | B34: impressions | C34: plays | D34: spend
A35: 45901 | B35: 738109 | C35: 183604 | D35: 500
A36: 45902 | B36: 1126668 | C36: 285089 | D36: 500
A37: 45903 | B37: 1103078 | C37: 278603 | D37: 500
A38: 45904 | B38: 1080083 | C38: 277666 | D38: 500
A39: 45905 | B39: 1866535 | C39: 491530 | D39: 500
A40: 45906 | B40: 1864690 | C40: 502206 | D40: 500
A41: 45907 | B41: 1742812 | C41: 469323 | D41: 500
A42: 45908 | B42: 1825867 | C42: 486287 | D42: 500
A43: 45909 | B43: 1880579 | C43: 505962 | D43: 500
A44: 45910 | B44: 1862514 | C44: 497137 | D44: 500
A45: 45911 | B45: 1822417 | C45: 482299 | D45: 500
A46: 45912 | B46: 1787024 | C46: 474525 | D46: 500
... A64: 45930 | B64: 150942 | C64: 40246 | D64: 50
A65: total | B65: 34854161 | C65: 9292386 | D65: 14730

Sheet salesforce
A1: Firebase Id | B1: IAB Venue Type | C1: Vistar Venue Type | D1: Account Name | E1: Shipping State/Province
A2: -Lm89I_2XS4Taz6KQV7u | B2: Entertainment | Restaurant and Bar | C2: Entertainment|Casual Dining | D2: Fionns Grant Park | E2: MB
A3: -N7vB4glPqShJ1qEHZau | B3: Entertainment | Restaurant and Bar | C3: Entertainment|Bars | D3: Taiv HQ | E3: TX
A4: -O9M57k5rIUKvFdpgX4O | B4: Entertainment | Restaurant and Bar | C4: Entertainment|Casual Dining | D4: Horus Cafe | E4: NY
A5: -O9WJ2SlG98VV_CKfYaP | B5: Entertainment | Restaurant and Bar | C5: Entertainment|Casual Dining | D5: Shotzee's Bar And Grill | E5: TX
A6: -O_CyzMLiCsHEy0Fka16 | B6: Entertainment | Restaurant and Bar | C6: Entertainment|Casual Dining | D6: Wonder Bar | E6: NJ
A7: -O_Czs_45eSb_6t3Phb5 | B7: Entertainment | Restaurant and Bar | C7: Entertainment|Casual Dining | D7: Dooney's Pub Voorhees | E7: NJ
A8: -O_D-Sxw48a26HdIwQug | B8: Entertainment | Restaurant and Bar | C8: Entertainment|Casual Dining | D8: Dooney's Pub Delran | E8: NJ
A9: -O_D1YnHKYI4O12HfWo- | B9: Entertainment | Restaurant and Bar | C9: Entertainment|Casual Dining | D9: Patrizia's Taverna | E9: NY
A10: -O_Ddul1kBg8t-1ZI3CW | B10: Entertainment | Restaurant and Bar | C10: Entertainment|Casual Dining | D10: Pikes Cinema Bar and Grill | E10: MD
A11: -O_DgPsRfCybGjUKPONk | B11: Entertainment | Restaurant and Bar | C11: Entertainment|Bars | D11: Del Webb Lakewood Ranch Lake House | E11: FL
A12: -O_DgSV0jE3wCUe-w7W3 | B12: Entertainment | Restaurant and Bar | C12: Entertainment|Casual Dining | D12: Element Restaurant & Bar | E12: NJ
... A396: -OVUEDAkqI222mx9hyen | B396: Entertainment | Restaurant and Bar | C396: Entertainment|Casual Dining | D396: Lamppost Pizza & The Post Pub | E396: CA
A397: -OVxBz_JouUWcpldiGDC | B397: Entertainment | Restaurant and Bar | C397: Entertainment|Casual Dining | D397: Drake's Hamburg
A398: -OVxxGawiz3mQPX0X5-Y | B398: Entertainment | Restaurant and Bar | C398: Entertainment|Bars | D398: Spring Street Tavern | E398: MN
A399: -OVyHA_b3rlATfkxVIP- | B399: Entertainment | Restaurant and Bar | C399: Entertainment|Casual Dining | D399: Broadway Pizza & Grill | E399: CA
A400: -OWaJl4RDToV5xMlV8gH | B400: Entertainment | Restaurant and Bar | C400: Entertainment|Bars | D400: Hook & Reel Cajun Seafood & Bar - West Orange | E400: NJ
A401: -OWblhB7OG_Z6jVFND6D | B401: Entertainment | Restaurant and Bar | C401: Entertainment|Casual Dining | D401: Los carnales tex mex grill | E401: VA
A402: -OWbownzrRMJDVMuEkxu | B402: Entertainment | Restaurant and Bar | C402: Entertainment|Casual Dining | D402: 4th Line Pub & Grill | E402: MB
A403: -OWGtV2G4_OFOkHUXc5D | B403: Entertainment | Restaurant and Bar | C403: Entertainment|Casual Dining | D403: Agua 301 Restaurant | E403: DC
A404: -OWMbmoY_fJT815GS_fw | B404: Entertainment | Restaurant and Bar | C404: Entertainment|Bars | D404: Scorpion Boston | E404: MA
A405: -OWMkiIjQT5mvzvucTCO | B405: Entertainment | Restaurant and Bar | C405: Entertainment|Casual Dining | D405: Bar Italia | E405: MB
A406: -OWMPpCz21C7RCDzNZxD | B406: Entertainment | Restaurant and Bar | C406: Entertainment|Bars | D406: Hastings Bierstube | E406: MN
A407: -OWMQVXfnAEWqGL7BhYW | B407: Entertainment | Restaurant and Bar | C407: Entertainment|Bars | D407: JW's Bierstube | E407: MN
A408: -OWMXxI_S4-XIXwloawU | B408: Entertainment | Restaurant and Bar | C408: Entertainment|Bars | D408: Scorpion Bar Patriot Place | E408: MA
A409: -OWMYfwuU9hJMdRrJ-at | B409: Entertainment | Restaurant and Bar | C409: Entertainment|Bars | D409: PLAY Boston | E409: MA
... A3375: -O1TZhl2ajhoccc0Bg_A | B3375: Entertainment | Recreational | C3375: Entertainment|Recreational Locations | D3375: Reach Reality Studios | E3375: NY
A3376: RETAIL
A3377: Firebase Id | B3377: IAB Venue Type | C3377: Vistar Venue Type | D3377: Account Name | E3377: Shipping State/Province
A3378: -N7vB4glPqShJ1qEHZau | B3378: Entertainment | Restaurant and Bar | C3378: Entertainment|Bars | D3378: Taiv HQ | E3378: TX
A3379: -O9M57k5rIUKvFdpgX4O | B3379: Entertainment | Restaurant and Bar | C3379: Entertainment|Casual Dining | D3379: Horus Cafe | E3379: NY
A3380: -O9WJ2SlG98VV_CKfYaP | B3380: Entertainment | Restaurant and Bar | C3380: Entertainment|Casual Dining | D3380: Shotzee's Bar And Grill | E3380: TX
A3381: -O_CyzMLiCsHEy0Fka16 | B3381: Entertainment | Restaurant and Bar | C3381: Entertainment|Casual Dining | D3381: Wonder Bar | E3381: NJ
A3382: -O_Czs_45eSb_6t3Phb5 | B3382: Entertainment | Restaurant and Bar | C3382: Entertainment|Casual Dining | D3382: Dooney's Pub Voorhees | E3382: NJ
A3383: -O_D-Sxw48a26HdIwQug | B3383: Entertainment | Restaurant and Bar | C3383: Entertainment|Casual Dining | D3383: Dooney's Pub Delran | E3383: NJ
A3384: -O_D1YnHKYI4O12HfWo- | B3384: Entertainment | Restaurant and Bar | C3384: Entertainment|Casual Dining | D3384: Patrizia's Taverna | E3384: NY
A3385: -O_Ddul1kBg8t-1ZI3CW | B3385: Entertainment | Restaurant and Bar | C3385: Entertainment|Casual Dining | D3385: Pikes Cinema Bar and Grill | E3385: MD
A3386: -O_DgPsRfCybGjUKPONk | B3386: Entertainment | Restaurant and Bar | C3386: Entertainment|Bars | D3386: Del Webb Lakewood Ranch Lake House | E3386: FL
A3387: -O_DgSV0jE3wCUe-w7W3 | B3387: Entertainment | Restaurant and Bar | C3387: Entertainment|Casual Dining | D3387: Element Restaurant & Bar | E3387: NJ
A3388: -O_ELZCxAK2_XLN59zf0 | B3388: Entertainment | Restaurant and Bar | C3388: Entertainment|Casual Dining | D3388: The Oceanview Inn & Sports Pub | E3388: FL
...
